
API Logic Project Server Setup (01JP90FC418VGZAH8DMNCEEY4M) Starting with CLI args: 
.. api_logic_server_run.py

Created August 03, 2024 09:34:01 at /opt/projects/by-ulid/01JP90FC418VGZAH8DMNCEEY4M

Traceback (most recent call last):
  File "/usr/local/lib/python3.12/site-packages/sqlalchemy/engine/base.py", line 1968, in _exec_single_context
    self.dialect.do_execute(
  File "/usr/local/lib/python3.12/site-packages/sqlalchemy/engine/default.py", line 920, in do_execute
    cursor.execute(statement, parameters)
sqlite3.OperationalError: near "(": syntax error

The above exception was the direct cause of the following exception:

Traceback (most recent call last):
  File "/opt/projects/by-ulid/01JP90FC418VGZAH8DMNCEEY4M/api_logic_server_run.py", line 98, in <module>
    server_setup.api_logic_server_setup(flask_app, args)
  File "/opt/projects/by-ulid/01JP90FC418VGZAH8DMNCEEY4M/config/server_setup.py", line 311, in api_logic_server_setup
    from api import expose_api_models, customize_api
  File "/opt/projects/by-ulid/01JP90FC418VGZAH8DMNCEEY4M/api/customize_api.py", line 7, in <module>
    from api.landing_page import add_landing_page
  File "/opt/projects/by-ulid/01JP90FC418VGZAH8DMNCEEY4M/api/landing_page/__init__.py", line 7, in <module>
    from database.spa_models.spa_page import SPASection, SPAPage, SPAComponent
  File "/opt/projects/by-ulid/01JP90FC418VGZAH8DMNCEEY4M/database/spa_models/spa_page.py", line 196, in <module>
    Base.metadata.create_all(engine)
  File "/usr/local/lib/python3.12/site-packages/sqlalchemy/sql/schema.py", line 5796, in create_all
    bind._run_ddl_visitor(
  File "/usr/local/lib/python3.12/site-packages/sqlalchemy/engine/base.py", line 3244, in _run_ddl_visitor
    conn._run_ddl_visitor(visitorcallable, element, **kwargs)
  File "/usr/local/lib/python3.12/site-packages/sqlalchemy/engine/base.py", line 2448, in _run_ddl_visitor
    visitorcallable(self.dialect, self, **kwargs).traverse_single(element)
  File "/usr/local/lib/python3.12/site-packages/sqlalchemy/sql/visitors.py", line 670, in traverse_single
    return meth(obj, **kw)
           ^^^^^^^^^^^^^^^
  File "/usr/local/lib/python3.12/site-packages/sqlalchemy/sql/ddl.py", line 922, in visit_metadata
    self.traverse_single(
  File "/usr/local/lib/python3.12/site-packages/sqlalchemy/sql/visitors.py", line 670, in traverse_single
    return meth(obj, **kw)
           ^^^^^^^^^^^^^^^
  File "/usr/local/lib/python3.12/site-packages/sqlalchemy/sql/ddl.py", line 961, in visit_table
    )._invoke_with(self.connection)
      ^^^^^^^^^^^^^^^^^^^^^^^^^^^^^
  File "/usr/local/lib/python3.12/site-packages/sqlalchemy/sql/ddl.py", line 315, in _invoke_with
    return bind.execute(self)
           ^^^^^^^^^^^^^^^^^^
  File "/usr/local/lib/python3.12/site-packages/sqlalchemy/engine/base.py", line 1413, in execute
    return meth(
           ^^^^^
  File "/usr/local/lib/python3.12/site-packages/sqlalchemy/sql/ddl.py", line 181, in _execute_on_connection
    return connection._execute_ddl(
           ^^^^^^^^^^^^^^^^^^^^^^^^
  File "/usr/local/lib/python3.12/site-packages/sqlalchemy/engine/base.py", line 1525, in _execute_ddl
    ret = self._execute_context(
          ^^^^^^^^^^^^^^^^^^^^^^
  File "/usr/local/lib/python3.12/site-packages/sqlalchemy/engine/base.py", line 1846, in _execute_context
    return self._exec_single_context(
           ^^^^^^^^^^^^^^^^^^^^^^^^^^
  File "/usr/local/lib/python3.12/site-packages/sqlalchemy/engine/base.py", line 1987, in _exec_single_context
    self._handle_dbapi_exception(
  File "/usr/local/lib/python3.12/site-packages/sqlalchemy/engine/base.py", line 2344, in _handle_dbapi_exception
    raise sqlalchemy_exception.with_traceback(exc_info[2]) from e
  File "/usr/local/lib/python3.12/site-packages/sqlalchemy/engine/base.py", line 1968, in _exec_single_context
    self.dialect.do_execute(
  File "/usr/local/lib/python3.12/site-packages/sqlalchemy/engine/default.py", line 920, in do_execute
    cursor.execute(statement, parameters)
sqlalchemy.exc.OperationalError: (sqlite3.OperationalError) near "(": syntax error
[SQL: 
CREATE TABLE device_types (
	"unique_id" INTEGER DEFAULT nextval('device_types_unique_id_seq'::regclass) NOT NULL, 
	"device_type" TEXT NOT NULL, 
	"create_date" DATETIME DEFAULT CURRENT_TIMESTAMP, 
	"update_date" DATETIME DEFAULT CURRENT_TIMESTAMP, 
	"is_inactive" BOOLEAN DEFAULT false, 
	PRIMARY KEY ("unique_id"), 
	UNIQUE ("device_type")
)

]
(Background on this error at: https://sqlalche.me/e/20/e3q8)

API Logic Project Server Setup (01JP90FC418VGZAH8DMNCEEY4M) Starting with CLI args: 
.. api_logic_server_run.py

Created August 03, 2024 09:34:01 at /opt/projects/by-ulid/01JP90FC418VGZAH8DMNCEEY4M

Traceback (most recent call last):
  File "/usr/local/lib/python3.12/site-packages/sqlalchemy/engine/base.py", line 1968, in _exec_single_context
    self.dialect.do_execute(
  File "/usr/local/lib/python3.12/site-packages/sqlalchemy/engine/default.py", line 920, in do_execute
    cursor.execute(statement, parameters)
sqlite3.OperationalError: near "(": syntax error

The above exception was the direct cause of the following exception:

Traceback (most recent call last):
  File "/opt/projects/by-ulid/01JP90FC418VGZAH8DMNCEEY4M/api_logic_server_run.py", line 98, in <module>
    server_setup.api_logic_server_setup(flask_app, args)
  File "/opt/projects/by-ulid/01JP90FC418VGZAH8DMNCEEY4M/config/server_setup.py", line 311, in api_logic_server_setup
    from api import expose_api_models, customize_api
  File "/opt/projects/by-ulid/01JP90FC418VGZAH8DMNCEEY4M/api/customize_api.py", line 7, in <module>
    from api.landing_page import add_landing_page
  File "/opt/projects/by-ulid/01JP90FC418VGZAH8DMNCEEY4M/api/landing_page/__init__.py", line 7, in <module>
    from database.spa_models.spa_page import SPASection, SPAPage, SPAComponent
  File "/opt/projects/by-ulid/01JP90FC418VGZAH8DMNCEEY4M/database/spa_models/spa_page.py", line 196, in <module>
    Base.metadata.create_all(engine)
  File "/usr/local/lib/python3.12/site-packages/sqlalchemy/sql/schema.py", line 5796, in create_all
    bind._run_ddl_visitor(
  File "/usr/local/lib/python3.12/site-packages/sqlalchemy/engine/base.py", line 3244, in _run_ddl_visitor
    conn._run_ddl_visitor(visitorcallable, element, **kwargs)
  File "/usr/local/lib/python3.12/site-packages/sqlalchemy/engine/base.py", line 2448, in _run_ddl_visitor
    visitorcallable(self.dialect, self, **kwargs).traverse_single(element)
  File "/usr/local/lib/python3.12/site-packages/sqlalchemy/sql/visitors.py", line 670, in traverse_single
    return meth(obj, **kw)
           ^^^^^^^^^^^^^^^
  File "/usr/local/lib/python3.12/site-packages/sqlalchemy/sql/ddl.py", line 922, in visit_metadata
    self.traverse_single(
  File "/usr/local/lib/python3.12/site-packages/sqlalchemy/sql/visitors.py", line 670, in traverse_single
    return meth(obj, **kw)
           ^^^^^^^^^^^^^^^
  File "/usr/local/lib/python3.12/site-packages/sqlalchemy/sql/ddl.py", line 961, in visit_table
    )._invoke_with(self.connection)
      ^^^^^^^^^^^^^^^^^^^^^^^^^^^^^
  File "/usr/local/lib/python3.12/site-packages/sqlalchemy/sql/ddl.py", line 315, in _invoke_with
    return bind.execute(self)
           ^^^^^^^^^^^^^^^^^^
  File "/usr/local/lib/python3.12/site-packages/sqlalchemy/engine/base.py", line 1413, in execute
    return meth(
           ^^^^^
  File "/usr/local/lib/python3.12/site-packages/sqlalchemy/sql/ddl.py", line 181, in _execute_on_connection
    return connection._execute_ddl(
           ^^^^^^^^^^^^^^^^^^^^^^^^
  File "/usr/local/lib/python3.12/site-packages/sqlalchemy/engine/base.py", line 1525, in _execute_ddl
    ret = self._execute_context(
          ^^^^^^^^^^^^^^^^^^^^^^
  File "/usr/local/lib/python3.12/site-packages/sqlalchemy/engine/base.py", line 1846, in _execute_context
    return self._exec_single_context(
           ^^^^^^^^^^^^^^^^^^^^^^^^^^
  File "/usr/local/lib/python3.12/site-packages/sqlalchemy/engine/base.py", line 1987, in _exec_single_context
    self._handle_dbapi_exception(
  File "/usr/local/lib/python3.12/site-packages/sqlalchemy/engine/base.py", line 2344, in _handle_dbapi_exception
    raise sqlalchemy_exception.with_traceback(exc_info[2]) from e
  File "/usr/local/lib/python3.12/site-packages/sqlalchemy/engine/base.py", line 1968, in _exec_single_context
    self.dialect.do_execute(
  File "/usr/local/lib/python3.12/site-packages/sqlalchemy/engine/default.py", line 920, in do_execute
    cursor.execute(statement, parameters)
sqlalchemy.exc.OperationalError: (sqlite3.OperationalError) near "(": syntax error
[SQL: 
CREATE TABLE device_types (
	"unique_id" INTEGER DEFAULT nextval('device_types_unique_id_seq'::regclass) NOT NULL, 
	"device_type" TEXT NOT NULL, 
	"create_date" DATETIME DEFAULT CURRENT_TIMESTAMP, 
	"update_date" DATETIME DEFAULT CURRENT_TIMESTAMP, 
	"is_inactive" BOOLEAN DEFAULT false, 
	PRIMARY KEY ("unique_id"), 
	UNIQUE ("device_type")
)

]
(Background on this error at: https://sqlalche.me/e/20/e3q8)
